Workbook
Name Amount: Expenses!$E$2:$E$114
Name Category: Expenses!$C$5:$C$62
Name Date: Expenses!$A$2:$A$114
Name Description: Expenses!$D$2:$D$114
Name Division: Expenses!$D$5:$D$62
Name Main_Category: Expenses!$C$2:$C$114
Name Slicer_Country_Group: #N/A
Name Slicer_Month: #N/A
Name Total_Expenses: Expenses!$H$5:$H$62

Sheet Reservations Plan
A1: 45809
B2: Sun | C2: Mon | D2: Tue | E2: Wed | F2: Thu | G2: Fri | H2: Sat | I2: Sun | J2: Mon | K2: Tue | L2: Wed | M2: Thu | N2: Fri | O2: Sat | P2: Sun | Q2: Mon | R2: Tue | S2: Wed | T2: Thu | U2: Fri | V2: Sat | W2: Sun | X2: Mon | Y2: Tue | Z2: Wed | AA2: Thu | AB2: Fri | AC2: Sat | AD2: Sun | AE2: Mon
B3: 1 | C3: 2 | D3: 3 | E3: 4 | F3: 5 | G3: 6 | H3: 7 | I3: 8 | J3: 9 | K3: 10 | L3: 11 | M3: 12 | N3: 13 | O3: 14 | P3: 15 | Q3: 16 | R3: 17 | S3: 18 | T3: 19 | U3: 20 | V3: 21 | W3: 22 | X3: 23 | Y3: 24 | Z3: 25 | AA3: 26 | AB3: 27 | AC3: 28 | AD3: 29 | AE3: 30 | AH3: R.N. | AI3: Occupancy
A4: 1 | B4: 0 | C4: 0 | D4: 0 | E4: 0 | F4: 0 | G4: 0 | H4: 0 | I4: 0 | J4: 0 | K4: 0 | L4: 0 | M4: 0 | N4: 0 | O4: 0 | P4: 0 | Q4: 0 | R4: 0 | S4: C036 | Y4: 0 | Z4: C032 | AH4: 1 | AI4: =(30-(COUNTIF(B4:AE4,0)))/30 -> 0.4
A5: 2 | B5: 0 | C5: 0 | D5: 0 | E5: 0 | F5: C044 | I5: 0 | J5: 0 | K5: 0 | L5: 0 | M5: 0 | N5: 0 | O5: 0 | P5: 0 | Q5: C034 | Y5: C019 | AE5: C087 | AH5: 2 | AI5: =(30-(COUNTIF(B5:AE5,0)))/30 -> 0.6
A6: 3 | B6: 0 | C6: 0 | D6: 0 | E6: 0 | F6: 0 | G6: 0 | H6: 0 | I6: 0 | J6: 0 | K6: 0 | L6: 0 | M6: 0 | N6: 0 | O6: 0 | P6: 0 | Q6: 0 | R6: 0 | S6: 0 | T6: 0 | U6: C068 | X6: 0 | Y6: C016 | AH6: 3 | AI6: =(30-(COUNTIF(B6:AE6,0)))/30 -> 0.33333333
A7: 4 | B7: 0 | C7: 0 | D7: 0 | E7: 0 | F7: 0 | G7: 0 | H7: 0 | I7: 0 | J7: 0 | K7: 0 | L7: 0 | M7: 0 | N7: 0 | O7: 0 | P7: 0 | Q7: 0 | R7: 0 | S7: 0 | T7: C050 | W7: C076 | Y7: C016 | AH7: 4 | AI7: =(30-(COUNTIF(B7:AE7,0)))/30 -> 0.4
A8: 5 | B8: 0 | C8: 0 | D8: 0 | E8: 0 | F8: 0 | G8: 0 | H8: 0 | I8: 0 | J8: 0 | K8: C011 | W8: C021 | AC8: 0 | AD8: 0 | AE8: 0 | AH8: 5 | AI8: =(30-(COUNTIF(B8:AE8,0)))/30 -> 0.6
A9: 6 | B9: 0 | C9: 0 | D9: 0 | E9: 0 | F9: 0 | G9: 0 | H9: 0 | I9: 0 | J9: 0 | K9: 0 | L9: 0 | M9: 0 | N9: 0 | O9: 0 | P9: 0 | Q9: 0 | R9: 0 | S9: 0 | T9: 0 | U9: C063 | Y9: C070 | AE9: 0 | AH9: 6 | AI9: =(30-(COUNTIF(B9:AE9,0)))/30 -> 0.33333333
A10: 7 | B10: 0 | C10: 0 | D10: 0 | E10: 0 | F10: 0 | G10: 0 | H10: 0 | I10: 0 | J10: 0 | K10: 0 | L10: 0 | M10: 0 | N10: 0 | O10: 0 | P10: 0 | Q10: 0 | R10: 0 | S10: 0 | T10: 0 | U10: C037 | AC10: C084 | AE10: 0 | AH10: 7 | AI10: =(30-(COUNTIF(B10:AE10,0)))/30 -> 0.33333333
A11: 8 | B11: 0 | C11: 0 | D11: 0 | E11: 0 | F11: 0 | G11: 0 | H11: 0 | I11: 0 | J11: 0 | K11: 0 | L11: 0 | M11: 0 | N11: 0 | O11: 0 | P11: 0 | Q11: 0 | R11: 0 | S11: 0 | T11: 0 | U11: C022 | AD11: 0 | AE11: 0 | AH11: 8 | AI11: =(30-(COUNTIF(B11:AE11,0)))/30 -> 0.3
A12: 101 | B12: 0 | C12: 0 | D12: 0 | E12: 0 | F12: 0 | G12: 0 | H12: 0 | I12: C041 | J12: 0 | K12: 0 | L12: 0 | M12: 0 | N12: 0 | O12: 0 | P12: 0 | Q12: 0 | R12: 0 | S12: 0 | T12: C056 | AH12: 101 | AI12: =(30-(COUNTIF(B12:AE12,0)))/30 -> 0.43333333
A13: 102 | B13: 0 | C13: 0 | D13: 0 | E13: 0 | F13: 0 | G13: C017 | I13: 0 | J13: 0 | K13: 0 | L13: 0 | M13: 0 | N13: 0 | O13: 0 | P13: C018/Tsiniani | V13: C048 | Y13: C023 | AH13: 102 | AI13: =(30-(COUNTIF(B13:AE13,0)))/30 -> 0.6
A14: 103 | B14: 0 | C14: 0 | D14: 0 | E14: 0 | F14: 0 | G14: C045 | I14: 0 | J14: 0 | K14: 0 | L14: 0 | M14: 0 | N14: 0 | O14: 0 | P14: 0 | Q14: 0 | R14: 0 | S14: 0 | T14: 0 | U14: C069 | W14: 0 | X14: C038 | AE14: 0 | AH14: 103 | AI14: =(30-(COUNTIF(B14:AE14,0)))/30 -> 0.36666667
A15: 104 | B15: 0 | C15: 0 | D15: 0 | E15: 0 | F15: 0 | G15: C017 | I15: 0 | J15: 0 | K15: 0 | L15: 0 | M15: 0 | N15: C033 | X15: C038 | AE15: 0 | AH15: 104 | AI15: =(30-(COUNTIF(B15:AE15,0)))/30 -> 0.63333333
A16: 105 | B16: 0 | C16: 0 | D16: 0 | E16: 0 | F16: 0 | G16: 0 | H16: C035 | J16: 0 | K16: 0 | L16: 0 | M16: 0 | N16: 0 | O16: 0 | P16: 0 | Q16: 0 | R16: 0 | S16: 0 | T16: 0 | U16: 0 | V16: 0 | W16: 0 | X16: C043 | AC16: C085 | AD16: 0 | AE16: C086 | AH16: 105 | AI16: =(30-(COUNTIF(B16:AE16,0)))/30 -> 0.3
A17: 106 | B17: 0 | C17: 0 | D17: 0 | E17: 0 | F17: 0 | G17: 0 | H17: C049 | J17: 0 | K17: 0 | L17: 0 | M17: 0 | N17: 0 | O17: 0 | P17: 0 | Q17: 0 | R17: 0 | S17: 0 | T17: C051 | W17: 0 | X17: C043 | AC17: C079 | AD17: C012 | AH17: 106 | AI17: =(30-(COUNTIF(B17:AE17,0)))/30 -> 0.43333333
A18: 107 | B18: 0 | C18: 0 | D18: 0 | E18: 0 | F18: 0 | G18: 0 | H18: C035 | J18: 0 | K18: 0 | L18: 0 | M18: C042 | Z18: C054 | AH18: 107 | AI18: =(30-(COUNTIF(B18:AE18,0)))/30 -> 0.7
A19: 108 | B19: 0 | C19: 0 | D19: 0 | E19: 0 | F19: 0 | G19: C020 | M19: 0 | N19: C003 | X19: C073 | AC19: 0 | AD19: C012 | AH19: 108 | AI19: =(30-(COUNTIF(B19:AE19,0)))/30 -> 0.76666667
A22: 45839
B23: Tue | C23: Wed | D23: Thu | E23: Fri | F23: Sat | G23: Sun | H23: Mon | I23: Tue | J23: Wed | K23: Thu | L23: Fri | M23: Sat | N23: Sun | O23: Mon | P23: Tue | Q23: Wed | R23: Thu | S23: Fri | T23: Sat | U23: Sun | V23: Mon | W23: Tue | X23: Wed | Y23: Thu | Z23: Fri | AA23: Sat | AB23: Sun | AC23: Mon | AD23: Tue | AE23: Wed | AF23: Thu
B24: 1 | C24: 2 | D24: 3 | E24: 4 | F24: 5 | G24: 6 | H24: 7 | I24: 8 | J24: 9 | K24: 10 | L24: 11 | M24: 12 | N24: 13 | O24: 14 | P24: 15 | Q24: 16 | R24: 17 | S24: 18 | T24: 19 | U24: 20 | V24: 21 | W24: 22 | X24: 23 | Y24: 24 | Z24: 25 | AA24: 26 | AB24: 27 | AC24: 28 | AD24: 29 | AE24: 30 | AF24: 31 | AH24: R.N. | AI24: Occupancy
A25: 1 | B25: C047 | L25: C059 | N25: C105 | X25: C115 | AC25: C090 | AH25: 1 | AI25: =(30-(COUNTIF(B25:AF25,0)))/30 -> 1
A26: 2 | B26: C087 | J26: 0 | K26: 0 | L26: C102 | T26: C080 | U26: 0 | V26: C024 | AH26: 2 | AI26: =(30-(COUNTIF(B26:AF26,0)))/30 -> 0.9
A27: 3 | B27: C080 | F27: C056 | J27: 0 | K27: 0 | L27: 0 | M27: C071 | T27: C113 | U27: 0 | V27: C024 | AH27: 3 | AI27: =(30-(COUNTIF(B27:AF27,0)))/30 -> 0.86666667
A28: 4 | B28: 0 | C28: 0 | D28: 0 | E28: 0 | F28: 0 | G28: 0 | H28: 0 | I28: 0 | J28: 0 | K28: 0 | L28: 0 | M28: 0 | N28: C014 | X28: 0 | Y28: C095 | AH28: 4 | AI28: =(30-(COUNTIF(B28:AF28,0)))/30 -> 0.56666667
A29: 5 | B29: 0 | C29: C013 | J29: C005 | Y29: C099 | AD29: 0 | AE29: 0 | AF29: 0 | AH29: 5 | AI29: =(30-(COUNTIF(B29:AF29,0)))/30 -> 0.86666667
A30: 6 | B30: 0 | C30: 0 | D30: 0 | E30: 0 | F30: 0 | G30: 0 | H30: 0 | I30: 0 | J30: 0 | K30: 0 | L30: 0 | M30: 0 | N30: 0 | O30: 0 | P30: 0 | Q30: C011 | V30: C009 | AH30: 6 | AI30: =(30-(COUNTIF(B30:AF30,0)))/30 -> 0.5
A31: 7 | B31: C088/Vlado | K31: 0 | L31: C001 | Z31: C106 | AF31: 0 | AH31: 7 | AI31: =(30-(COUNTIF(B31:AF31,0)))/30 -> 0.93333333
A32: 8 | B32: C088/Vlado | K32: C100 | R32: C098 | AA32: C111 | AB32: C096 | AH32: 8 | AI32: =(30-(COUNTIF(B32:AF32,0)))/30 -> 1
A33: 101 | B33: C056 | F33: C045 | N33: 0 | O33: 0 | P33: 0 | Q33: 0 | R33: C053 | AA33: C008 | AH33: 101 | AI33: =(30-(COUNTIF(B33:AF33,0)))/30 -> 0.86666667
A34: 102 | B34: C023 | E34: C078 | H34: C025 | R34: C083 | W34: C062 | AD34: 0 | AE34: 0 | AF34: 0 | AH34: 102 | AI34: =(30-(COUNTIF(B34:AF34,0)))/30 -> 0.9
A35: 103 | B35: C015 | L35: C007 | U35: C111 | AA35: C060 | AH35: 103 | AI35: =(30-(COUNTIF(B35:AF35,0)))/30 -> 1
A36: 104 | B36: C015 | L36: 0 | M36: C080 | N36: 0 | O36: C039 | T36: C101 | U36: C093 | AC36: C118 | AD36: C121 | AF36: 0 | AH36: 104 | AI36: =(30-(COUNTIF(B36:AF36,0)))/30 -> 0.9
A37: 105 | B37: C086 | G37: C015 | J37: C075 | Q37: C027 | Z37: C118 | AC37: C072 | AH37: 105 | AI37: =(30-(COUNTIF(B37:AF37,0)))/30 -> 1
A38: 106 | B38: C012 | J38: 0 | K38: 0 | L38: 0 | M38: 0 | N38: C104 | P38: C026 | AD38: C040 | AH38: 106 | AI38: =(30-(COUNTIF(B38:AF38,0)))/30 -> 0.86666667
A39: 107 | B39: C081 | F39: C074 | N39: 0 | O39: 0 | P39: 0 | Q39: 0 | R39: 0 | S39: C110 | V39: C057 | AA39: C112 | AC39: C091 | AH39: 107 | AI39: =(30-(COUNTIF(B39:AF39,0)))/30 -> 0.83333333
A40: 108 | B40: C012 | J40: C077/Rigas | O40: 0 | P40: C108 | S40: 0 | T40: 0 | U40: C094 | AC40: C010 | AH40: 108 | AI40: =(30-(COUNTIF(B40:AF40,0)))/30 -> 0.9
A44: 45870
B45: Fri | C45: Sat | D45: Sun | E45: Mon | F45: Tue | G45: Wed | H45: Thu | I45: Fri | J45: Sat | K45: Sun | L45: Mon | M45: Tue | N45: Wed | O45: Thu | P45: Fri | Q45: Sat | R45: Sun | S45: Mon | T45: Tue | U45: Wed | V45: Thu | W45: Fri | X45: Sat | Y45: Sun | Z45: Mon | AA45: Tue | AB45: Wed | AC45: Thu | AD45: Fri | AE45: Sat | AF45: Sun
...

Sheet Room Occupancy
B2: R.N. | C2: Occupancy June | D2: Occupancy July | E2: Occupancy August | F2: Occupancy September | G2: Total Avg Room Occupancy
B3: 1 | C3: 0.4 | D3: 1 | E3: 0.96666667 | F3: 0.63333333 | G3: =AVERAGE(Table3[[#This Row],[Occupancy June]:[Occupancy September]]) -> 0.75
B4: 2 | C4: 0.6 | D4: 0.9 | E4: 0.96666667 | F4: 0.26666667 | G4: =AVERAGE(Table3[[#This Row],[Occupancy June]:[Occupancy September]]) -> 0.68333333
B5: 3 | C5: 0.33333333 | D5: 0.86666667 | E5: 1 | F5: 0.66666667 | G5: =AVERAGE(Table3[[#This Row],[Occupancy June]:[Occupancy September]]) -> 0.71666667
B6: 4 | C6: 0.4 | D6: 0.56666667 | E6: 1 | F6: 0.5 | G6: =AVERAGE(Table3[[#This Row],[Occupancy June]:[Occupancy September]]) -> 0.61666667
B7: 5 | C7: 0.6 | D7: 0.86666667 | E7: 0.96666667 | F7: 0.46666667 | G7: =AVERAGE(Table3[[#This Row],[Occupancy June]:[Occupancy September]]) -> 0.725
B8: 6 | C8: 0.33333333 | D8: 0.5 | E8: 0.76666667 | F8: 0.033333333 | G8: =AVERAGE(Table3[[#This Row],[Occupancy June]:[Occupancy September]]) -> 0.40833333
B9: 7 | C9: 0.33333333 | D9: 0.93333333 | E9: 0.96666667 | F9: 0.26666667 | G9: =AVERAGE(Table3[[#This Row],[Occupancy June]:[Occupancy September]]) -> 0.625
B10: 8 | C10: 0.3 | D10: 1 | E10: 0.93333333 | F10: 0.4 | G10: =AVERAGE(Table3[[#This Row],[Occupancy June]:[Occupancy September]]) -> 0.65833333
B11: 101 | C11: 0.43333333 | D11: 0.86666667 | E11: 0.9 | F11: 0.36666667 | G11: =AVERAGE(Table3[[#This Row],[Occupancy June]:[Occupancy September]]) -> 0.64166667
B12: 102 | C12: 0.6 | D12: 0.9 | E12: 0.96666667 | F12: 0.43333333 | G12: =AVERAGE(Table3[[#This Row],[Occupancy June]:[Occupancy September]]) -> 0.725
B13: 103 | C13: 0.36666667 | D13: 1 | E13: 0.9 | F13: 0.26666667 | G13: =AVERAGE(Table3[[#This Row],[Occupancy June]:[Occupancy September]]) -> 0.63333333
B14: 104 | C14: 0.63333333 | D14: 0.9 | E14: 0.93333333 | F14: 0.3 | G14: =AVERAGE(Table3[[#This Row],[Occupancy June]:[Occupancy September]]) -> 0.69166667
... B18: 108 | C18: 0.76666667 | D18: 0.9 | E18: 0.96666667 | F18: 0.5 | G18: =AVERAGE(Table3[[#This Row],[Occupancy June]:[Occupancy September]]) -> 0.78333333
B19: Total | C19: =SUBTOTAL(101,Table3[Occupancy June]) -> 0.47083333 | D19: =SUBTOTAL(101,Table3[Occupancy July]) -> 0.86875 | E19: =SUBTOTAL(101,Table3[Occupancy August]) -> 0.9375 | F19: =SUBTOTAL(101,Table3[Occupancy September]) -> 0.36041667

Sheet Guests 
A1: Guest ID | B1: Age | C1: Age Group | D1: Country | E1: Returning Guest
A2: C001 | B2: 59 | C2: 51 plus | D2: Serbia | E2: No
A3: C002 | B3: 37 | C3: 31-50 | D3: Austria | E3: Yes
A4: C003 | B4: 56 | C4: 51 plus | D4: Serbia | E4: Yes
A5: C004 | B5: 34 | C5: 31-50 | D5: Serbia | E5: Yes
A6: C005 | B6: 57 | C6: 51 plus | D6: Austria | E6: Yes
A7: C006 | B7: 54 | C7: 51 plus | D7: Serbia | E7: Yes
A8: C007 | B8: 48 | C8: 31-50 | D8: Serbia | E8: Yes
A9: C008 | B9: 42 | C9: 31-50 | D9: Serbia | E9: Yes
A10: C009 | B10: 58 | C10: 51 plus | D10: Serbia | E10: Yes
A11: C010 | B11: 50 | C11: 31-50 | D11: Serbia | E11: Yes
A12: C011 | B12: 78 | C12: 51 plus | D12: MKD | E12: Yes
A13: C012 | B13: 25 | C13: 18-30 | D13: Serbia | E13: No
... A52: C051 | B52: 51 | C52: 51 plus | D52: Greece | E52: No
A53: C052 | D53: Greece | E53: No
A54: C053 | B54: 75 | C54: 51 plus | D54: Greece | E54: Yes
A55: C054 | B55: 62 | C55: 51 plus | D55: Greece | E55: No
A56: C055 | B56: 42 | C56: 31-50 | D56: Greece | E56: No
A57: C056 | B57: 71 | C57: 51 plus | D57: Serbia | E57: Yes
A58: C057 | B58: 46 | C58: 31-50 | D58: Greece | E58: No
A59: C058 | D59: Greece | E59: No
A60: C059 | B60: 67 | C60: 51 plus | D60: Greece | E60: No
A61: C060 | B61: 61 | C61: 51 plus | D61: MKD | E61: Yes
A62: C061 | D62: Greece | E62: No
A63: C062 | B63: 43 | C63: 31-50 | D63: Serbia | E63: No
A64: C063 | B64: 58 | C64: 51 plus | D64: Greece | E64: Yes
A65: C064 | D65: Greece | E65: No
A66: C065 | B66: 67 | C66: 51 plus | D66: Serbia | E66: Yes
A67: C066 | B67: 50 | C67: 31-50 | D67: Greece | E67: Yes
A68: C067 | B68: 52 | C68: 51 plus | D68: MKD | E68: Yes
A69: C068 | B69: 51 | C69: 51 plus | D69: Greece | E69: Yes
A70: C069 | B70: 46 | C70: 31-50 | D70: Greece | E70: No
A71: C070 | B71: 74 | C71: 51 plus | D71: Greece | E71: Yes
A72: C071 | B72: 69 | C72: 51 plus | D72: Greece | E72: Yes
A73: C072 | B73: 34 | C73: 31-50 | D73: Serbia | E73: Yes
A74: C073 | B74: 53 | C74: 51 plus | D74: MKD | E74: No
A75: C074 | B75: 62 | C75: 51 plus | D75: Serbia | E75: Yes
A76: C075 | B76: 31 | C76: 31-50 | D76: Serbia | E76: No
A77: C076 | B77: 42 | C77: 31-50 | D77: Greece | E77: Yes
... A120: C119 | B120: 34 | C120: 31-50 | D120: MKD | E120: No
...

Sheet Bookings
A1: Booking ID | B1: Booking Status | C1: Guest ID | D1: Room No | E1: Total Guests | F1: Guest Type | G1: Guest Nationality | H1: Check-in | I1: Check-out | J1: Nights Stayed | K1: Price per Night | L1: Deposit | M1: Amount Due | N1: Total Revenue | O1: Month | P1: Booking Source | Q1: Contact Person
A2: 2025-001 | B2: confirmed | C2: C020 | D2: 108 | E2: 1 | F2: {=_xlfn.IFS(Bookings[[#This Row],[Total Guests]]=1,"Solo",Bookings[[#This Row],[Total Guests]]=2,"Couple",Bookings[[#This Row],[Total Guests]]>=3,"Family")} -> Solo | G2: =VLOOKUP(Bookings[[#This Row],[Guest ID]],Table1[],4,0) -> Greece | H2: 45814 | I2: 45820 | J2: =Bookings[[#This Row],[Check-out]]-Bookings[[#This Row],[Check-in]] -> 6 | K2: 30 | L2: 0 | M2: =(J2*K2)-L2 -> 180 | N2: =Bookings[[#This Row],[Nights Stayed]]*Bookings[[#This Row],[Price per Night]] -> 180 | O2: =TEXT(Bookings[[#This Row],[Check-in]],"mmm") -> Jun | P2: Phone Call | Q2: Dimitra
A3: 2025-002 | B3: confirmed | C3: C017 | D3: 104 | E3: 2 | F3: {=_xlfn.IFS(Bookings[[#This Row],[Total Guests]]=1,"Solo",Bookings[[#This Row],[Total Guests]]=2,"Couple",Bookings[[#This Row],[Total Guests]]>=3,"Family")} -> Couple | G3: =VLOOKUP(Bookings[[#This Row],[Guest ID]],Table1[],4,0) -> Serbia | H3: 45814 | I3: 45816 | J3: =Bookings[[#This Row],[Check-out]]-Bookings[[#This Row],[Check-in]] -> 2 | K3: 30 | L3: 0 | M3: =(J3*K3)-L3 -> 60 | N3: =Bookings[[#This Row],[Nights Stayed]]*Bookings[[#This Row],[Price per Night]] -> 60 | O3: =TEXT(Bookings[[#This Row],[Check-in]],"mmm") -> Jun | P3: Messaging Apps | Q3: Maria
A4: 2025-003 | B4: confirmed | C4: C017 | D4: 102 | E4: 3 | F4: {=_xlfn.IFS(Bookings[[#This Row],[Total Guests]]=1,"Solo",Bookings[[#This Row],[Total Guests]]=2,"Couple",Bookings[[#This Row],[Total Guests]]>=3,"Family")} -> Family | G4: =VLOOKUP(Bookings[[#This Row],[Guest ID]],Table1[],4,0) -> Serbia | H4: 45814 | I4: 45816 | J4: =Bookings[[#This Row],[Check-out]]-Bookings[[#This Row],[Check-in]] -> 2 | K4: 35 | L4: 0 | M4: =(J4*K4)-L4 -> 70 | N4: =Bookings[[#This Row],[Nights Stayed]]*Bookings[[#This Row],[Price per Night]] -> 70 | O4: =TEXT(Bookings[[#This Row],[Check-in]],"mmm") -> Jun | P4: Messaging Apps | Q4: Maria
A5: 2025-004 | B5: confirmed | C5: C011 | D5: 5 | E5: 4 | F5: {=_xlfn.IFS(Bookings[[#This Row],[Total Guests]]=1,"Solo",Bookings[[#This Row],[Total Guests]]=2,"Couple",Bookings[[#This Row],[Total Guests]]>=3,"Family")} -> Family | G5: =VLOOKUP(Bookings[[#This Row],[Guest ID]],Table1[],4,0) -> MKD | H5: 45818 | I5: 45830 | J5: =Bookings[[#This Row],[Check-out]]-Bookings[[#This Row],[Check-in]] -> 12 | K5: 40 | L5: 0 | M5: =(J5*K5)-L5 -> 480 | N5: =Bookings[[#This Row],[Nights Stayed]]*Bookings[[#This Row],[Price per Night]] -> 480 | O5: =TEXT(Bookings[[#This Row],[Check-in]],"mmm") -> Jun | P5: Messaging Apps | Q5: Maria
A6: 2025-005 | B6: confirmed | C6: C003 | D6: 108 | E6: 2 | F6: {=_xlfn.IFS(Bookings[[#This Row],[Total Guests]]=1,"Solo",Bookings[[#This Row],[Total Guests]]=2,"Couple",Bookings[[#This Row],[Total Guests]]>=3,"Family")} -> Couple | G6: =VLOOKUP(Bookings[[#This Row],[Guest ID]],Table1[],4,0) -> Serbia | H6: 45821 | I6: 45831 | J6: =Bookings[[#This Row],[Check-out]]-Bookings[[#This Row],[Check-in]] -> 10 | K6: 30 | L6: 0 | M6: =(J6*K6)-L6 -> 300 | N6: =Bookings[[#This Row],[Nights Stayed]]*Bookings[[#This Row],[Price per Night]] -> 300 | O6: =TEXT(Bookings[[#This Row],[Check-in]],"mmm") -> Jun | P6: Messaging Apps | Q6: Maria
A7: 2025-006 | B7: confirmed | C7: C018 | D7: 102 | E7: 3 | F7: {=_xlfn.IFS(Bookings[[#This Row],[Total Guests]]=1,"Solo",Bookings[[#This Row],[Total Guests]]=2,"Couple",Bookings[[#This Row],[Total Guests]]>=3,"Family")} -> Family | G7: =VLOOKUP(Bookings[[#This Row],[Guest ID]],Table1[],4,0) -> Greece | H7: 45823 | I7: 45829 | J7: =Bookings[[#This Row],[Check-out]]-Bookings[[#This Row],[Check-in]] -> 6 | K7: 40 | L7: 0 | M7: =(J7*K7)-L7 -> 240 | N7: =Bookings[[#This Row],[Nights Stayed]]*Bookings[[#This Row],[Price per Night]] -> 240 | O7: =TEXT(Bookings[[#This Row],[Check-in]],"mmm") -> Jun | P7: Phone Call | Q7: Dimitra
A8: 2025-007 | B8: confirmed | C8: C022 | D8: 8 | E8: 3 | F8: {=_xlfn.IFS(Bookings[[#This Row],[Total Guests]]=1,"Solo",Bookings[[#This Row],[Total Guests]]=2,"Couple",Bookings[[#This Row],[Total Guests]]>=3,"Family")} -> Family | G8: =VLOOKUP(Bookings[[#This Row],[Guest ID]],Table1[],4,0) -> Serbia | H8: 45828 | I8: 45837 | J8: =Bookings[[#This Row],[Check-out]]-Bookings[[#This Row],[Check-in]] -> 9 | K8: 37 | L8: 0 | M8: =(J8*K8)-L8 -> 333 | N8: =Bookings[[#This Row],[Nights Stayed]]*Bookings[[#This Row],[Price per Night]] -> 333 | O8: =TEXT(Bookings[[#This Row],[Check-in]],"mmm") -> Jun | P8: Grcka Info | Q8: Katerina
A9: 2025-008 | B9: confirmed | C9: C021 | D9: 5 | E9: 4 | F9: {=_xlfn.IFS(Bookings[[#This Row],[Total Guests]]=1,"Solo",Bookings[[#This Row],[Total Guests]]=2,"Couple",Bookings[[#This Row],[Total Guests]]>=3,"Family")} -> Family | G9: =VLOOKUP(Bookings[[#This Row],[Guest ID]],Table1[],4,0) -> Greece | H9: 45830 | I9: 45836 | J9: =Bookings[[#This Row],[Check-out]]-Bookings[[#This Row],[Check-in]] -> 6 | K9: 45 | L9: 0 | M9: =(J9*K9)-L9 -> 270 | N9: =Bookings[[#This Row],[Nights Stayed]]*Bookings[[#This Row],[Price per Night]] -> 270 | O9: =TEXT(Bookings[[#This Row],[Check-in]],"mmm") -> Jun | P9: Phone Call | Q9: Dimitra
A10: 2025-009 | B10: confirmed | C10: C019 | D10: 2 | E10: 2 | F10: {=_xlfn.IFS(Bookings[[#This Row],[Total Guests]]=1,"Solo",Bookings[[#This Row],[Total Guests]]=2,"Couple",Bookings[[#This Row],[Total Guests]]>=3,"Family")} -> Couple | G10: =VLOOKUP(Bookings[[#This Row],[Guest ID]],Table1[],4,0) -> Greece | H10: 45832 | I10: 45838 | J10: =Bookings[[#This Row],[Check-out]]-Bookings[[#This Row],[Check-in]] -> 6 | K10: 35 | L10: 0 | M10: =(J10*K10)-L10 -> 210 | N10: =Bookings[[#This Row],[Nights Stayed]]*Bookings[[#This Row],[Price per Night]] -> 210 | O10: =TEXT(Bookings[[#This Row],[Check-in]],"mmm") -> Jun | P10: Phone Call | Q10: Dimitra
A11: 2025-010 | B11: confirmed | C11: C016 | D11: 3 | E11: 2 | F11: {=_xlfn.IFS(Bookings[[#This Row],[Total Guests]]=1,"Solo",Bookings[[#This Row],[Total Guests]]=2,"Couple",Bookings[[#This Row],[Total Guests]]>=3,"Family")} -> Couple | G11: =VLOOKUP(Bookings[[#This Row],[Guest ID]],Table1[],4,0) -> Serbia | H11: 45832 | I11: 45839 | J11: =Bookings[[#This Row],[Check-out]]-Bookings[[#This Row],[Check-in]] -> 7 | K11: 30 | L11: 0 | M11: =(J11*K11)-L11 -> 210 | N11: =Bookings[[#This Row],[Nights Stayed]]*Bookings[[#This Row],[Price per Night]] -> 210 | O11: =TEXT(Bookings[[#This Row],[Check-in]],"mmm") -> Jun | P11: Messaging Apps | Q11: Maria
A12: 2025-011 | B12: confirmed | C12: C016 | D12: 4 | E12: 2 | F12: {=_xlfn.IFS(Bookings[[#This Row],[Total Guests]]=1,"Solo",Bookings[[#This Row],[Total Guests]]=2,"Couple",Bookings[[#This Row],[Total Guests]]>=3,"Family")} -> Couple | G12: =VLOOKUP(Bookings[[#This Row],[Guest ID]],Table1[],4,0) -> Serbia | H12: 45832 | I12: 45839 | J12: =Bookings[[#This Row],[Check-out]]-Bookings[[#This Row],[Check-in]] -> 7 | K12: 30 | L12: 0 | M12: =(J12*K12)-L12 -> 210 | N12: =Bookings[[#This Row],[Nights Stayed]]*Bookings[[#This Row],[Price per Night]] -> 210 | O12: =TEXT(Bookings[[#This Row],[Check-in]],"mmm") -> Jun | P12: Messaging Apps | Q12: Maria
A13: 2025-012 | B13: confirmed | C13: C023 | D13: 102 | E13: 2 | F13: {=_xlfn.IFS(Bookings[[#This Row],[Total Guests]]=1,"Solo",Bookings[[#This Row],[Total Guests]]=2,"Couple",Bookings[[#This Row],[Total Guests]]>=3,"Family")} -> Couple | G13: =VLOOKUP(Bookings[[#This Row],[Guest ID]],Table1[],4,0) -> Serbia | H13: 45832 | I13: 45842 | J13: =Bookings[[#This Row],[Check-out]]-Bookings[[#This Row],[Check-in]] -> 10 | K13: 32 | L13: 0 | M13: =(J13*K13)-L13 -> 320 | N13: =Bookings[[#This Row],[Nights Stayed]]*Bookings[[#This Row],[Price per Night]] -> 320 | O13: =TEXT(Bookings[[#This Row],[Check-in]],"mmm") -> Jun | P13: Messaging Apps | Q13: Katerina
... A189: 2025-188 | B189: confirmed | C189: C164 | D189: 103 | E189: 4 | F189: {=_xlfn.IFS(Bookings[[#This Row],[Total Guests]]=1,"Solo",Bookings[[#This Row],[Total Guests]]=2,"Couple",Bookings[[#This Row],[Total Guests]]>=3,"Family")} -> Family | G189: =VLOOKUP(Bookings[[#This Row],[Guest ID]],Table1[],4,0) -> MKD | H189: 45896 | I189: 45898 | J189: =Bookings[[#This Row],[Check-out]]-Bookings[[#This Row],[Check-in]] -> 2 | K189: 55 | L189: 0 | M189: =(J189*K189)-L189 -> 110 | N189: =Bookings[[#This Row],[Nights Stayed]]*Bookings[[#This Row],[Price per Night]] -> 110 | O189: =TEXT(Bookings[[#This Row],[Check-in]],"mmm") -> Aug | P189: Phone Call | Q189: Maria
A190: 2025-189 | B190: confirmed | C190: C158 | D190: 8 | E190: 3 | F190: {=_xlfn.IFS(Bookings[[#This Row],[Total Guests]]=1,"Solo",Bookings[[#This Row],[Total Guests]]=2,"Couple",Bookings[[#This Row],[Total Guests]]>=3,"Family")} -> Family | G190: =VLOOKUP(Bookings[[#This Row],[Guest ID]],Table1[],4,0) -> Greece | H190: 45893 | I190: 45899 | J190: =Bookings[[#This Row],[Check-out]]-Bookings[[#This Row],[Check-in]] -> 6 | K190: 50 | L190: 0 | M190: =J190*K190 -> 300 | N190: =Bookings[[#This Row],[Nights Stayed]]*Bookings[[#This Row],[Price per Night]] -> 300 | O190: =TEXT(Bookings[[#This Row],[Check-in]],"mmm") -> Aug | P190: Phone Call | Q190: Maria
A191: 2025-190 | B191: confirmed | C191: C065 | D191: 5 | E191: 4 | F191: {=_xlfn.IFS(Bookings[[#This Row],[Total Guests]]=1,"Solo",Bookings[[#This Row],[Total Guests]]=2,"Couple",Bookings[[#This Row],[Total Guests]]>=3,"Family")} -> Family | G191: =VLOOKUP(Bookings[[#This Row],[Guest ID]],Table1[],4,0) -> Serbia | H191: 45910 | I191: 45917 | J191: =Bookings[[#This Row],[Check-out]]-Bookings[[#This Row],[Check-in]] -> 7 | K191: 50 | L191: 0 | M191: =J191*K191 -> 350 | N191: =Bookings[[#This Row],[Nights Stayed]]*Bookings[[#This Row],[Price per Night]] -> 350 | O191: =TEXT(Bookings[[#This Row],[Check-in]],"mmm") -> Sep | P191: Messaging Apps | Q191: Katerina
A192: 2025-191 | B192: confirmed | C192: C153 | D192: 106 | E192: 3 | F192: {=_xlfn.IFS(Bookings[[#This Row],[Total Guests]]=1,"Solo",Bookings[[#This Row],[Total Guests]]=2,"Couple",Bookings[[#This Row],[Total Guests]]>=3,"Family")} -> Family | G192: =VLOOKUP(Bookings[[#This Row],[Guest ID]],Table1[],4,0) -> Serbia | H192: 45894 | I192: 45897 | J192: =Bookings[[#This Row],[Check-out]]-Bookings[[#This Row],[Check-in]] -> 3 | K192: 55 | L192: 0 | M192: =(J192*K192)-L192 -> 165 | N192: =Bookings[[#This Row],[Nights Stayed]]*Bookings[[#This Row],[Price per Night]] -> 165 | O192: =TEXT(Bookings[[#This Row],[Check-in]],"mmm") -> Aug | P192: Grcka Info | Q192: Maria
A193: 2025-192 | B193: confirmed | C193: C109 | D193: 107 | E193: 4 | F193: {=_xlfn.IFS(Bookings[[#This Row],[Total Guests]]=1,"Solo",Bookings[[#This Row],[Total Guests]]=2,"Couple",Bookings[[#This Row],[Total Guests]]>=3,"Family")} -> Family | G193: =VLOOKUP(Bookings[[#This Row],[Guest ID]],Table1[],4,0) -> Greece | H193: 45893 | I193: 45899 | J193: =Bookings[[#This Row],[Check-out]]-Bookings[[#This Row],[Check-in]] -> 6 | K193: 57 | L193: 0 | M193: =(J193*K193)-L193 -> 342 | N193: =Bookings[[#This Row],[Nights Stayed]]*Bookings[[#This Row],[Price per Night]] -> 342 | O193: =TEXT(Bookings[[#This Row],[Check-in]],"mmm") -> Aug | P193: Phone Call | Q193: Katerina
A194: 2025-193 | B194: confirmed | C194: C160 | D194: 103 | E194: 2 | F194: {=_xlfn.IFS(Bookings[[#This Row],[Total Guests]]=1,"Solo",Bookings[[#This Row],[Total Guests]]=2,"Couple",Bookings[[#This Row],[Total Guests]]>=3,"Family")} -> Couple | G194: =VLOOKUP(Bookings[[#This Row],[Guest ID]],Table1[],4,0) -> Greece | H194: 45893 | I194: 45894 | J194: =Bookings[[#This Row],[Check-out]]-Bookings[[#This Row],[Check-in]] -> 1 | K194: 50 | L194: 0 | M194: =(J194*K194)-L194 -> 50 | N194: =Bookings[[#This Row],[Nights Stayed]]*Bookings[[#This Row],[Price per Night]] -> 50 | O194: =TEXT(Bookings[[#This Row],[Check-in]],"mmm") -> Aug | P194: Phone Call | Q194: Maria
A195: 2025-194 | B195: confirmed | C195: C041 | D195: 8 | E195: 2 | F195: {=_xlfn.IFS(Bookings[[#This Row],[Total Guests]]=1,"Solo",Bookings[[#This Row],[Total Guests]]=2,"Couple",Bookings[[#This Row],[Total Guests]]>=3,"Family")} -> Couple | G195: =VLOOKUP(Bookings[[#This Row],[Guest ID]],Table1[],4,0) -> Greece | H195: 45892 | I195: 45893 | J195: =Bookings[[#This Row],[Check-out]]-Bookings[[#This Row],[Check-in]] -> 1 | K195: 50 | L195: 0 | M195: =(J195*K195)-L195 -> 50 | N195: =Bookings[[#This Row],[Nights Stayed]]*Bookings[[#This Row],[Price per Night]] -> 50 | O195: =TEXT(Bookings[[#This Row],[Check-in]],"mmm") -> Aug | P195: Phone Call | Q195: Dimitra
A196: 2025-195 | B196: confirmed | C196: C161 | D196: 105 | E196: 4 | F196: {=_xlfn.IFS(Bookings[[#This Row],[Total Guests]]=1,"Solo",Bookings[[#This Row],[Total Guests]]=2,"Couple",Bookings[[#This Row],[Total Guests]]>=3,"Family")} -> Family | G196: =VLOOKUP(Bookings[[#This Row],[Guest ID]],Table1[],4,0) -> Greece | H196: 45893 | I196: 45895 | J196: =Bookings[[#This Row],[Check-out]]-Bookings[[#This Row],[Check-in]] -> 2 | K196: 50 | L196: 0 | M196: =(J196*K196)-L196 -> 100 | N196: =Bookings[[#This Row],[Nights Stayed]]*Bookings[[#This Row],[Price per Night]] -> 100 | O196: =TEXT(Bookings[[#This Row],[Check-in]],"mmm") -> Aug | P196: Phone Call | Q196: Maria
A197: 2025-196 | B197: confirmed | C197: C162 | D197: 102 | E197: 3 | F197: {=_xlfn.IFS(Bookings[[#This Row],[Total Guests]]=1,"Solo",Bookings[[#This Row],[Total Guests]]=2,"Couple",Bookings[[#This Row],[Total Guests]]>=3,"Family")} -> Family | G197: =VLOOKUP(Bookings[[#This Row],[Guest ID]],Table1[],4,0) -> MKD | H197: 45893 | I197: 45900 | J197: =Bookings[[#This Row],[Check-out]]-Bookings[[#This Row],[Check-in]] -> 7 | K197: 50 | L197: 0 | M197: =(J197*K197)-L197 -> 350 | N197: =Bookings[[#This Row],[Nights Stayed]]*Bookings[[#This Row],[Price per Night]] -> 350 | O197: =TEXT(Bookings[[#This Row],[Check-in]],"mmm") -> Aug | P197: Walk in | Q197: Maria
A198: 2025-197 | B198: cancelled | C198: C165 | D198: 2 | E198: 2 | F198: {=_xlfn.IFS(Bookings[[#This Row],[Total Guests]]=1,"Solo",Bookings[[#This Row],[Total Guests]]=2,"Couple",Bookings[[#This Row],[Total Guests]]>=3,"Family")} -> Couple | G198: =VLOOKUP(Bookings[[#This Row],[Guest ID]],Table1[],4,0) -> Serbia | H198: 45906 | I198: 45908 | J198: =Bookings[[#This Row],[Check-out]]-Bookings[[#This Row],[Check-in]] -> 2 | K198: 42 | L198: 0 | M198: =(J198*K198)-L198 -> 84 | N198: =Bookings[[#This Row],[Nights Stayed]]*Bookings[[#This Row],[Price per Night]] -> 84 | O198: =TEXT(Bookings[[#This Row],[Check-in]],"mmm") -> Sep | P198: Messaging Apps | Q198: Katerina
A199: 2025-198 | B199: confirmed | C199: C167 | D199: 101 | E199: 2 | F199: {=_xlfn.IFS(Bookings[[#This Row],[Total Guests]]=1,"Solo",Bookings[[#This Row],[Total Guests]]=2,"Couple",Bookings[[#This Row],[Total Guests]]>=3,"Family")} -> Couple | G199: =VLOOKUP(Bookings[[#This Row],[Guest ID]],Table1[],4,0) -> Greece | H199: 45897 | I199: 45899 | J199: =Bookings[[#This Row],[Check-out]]-Bookings[[#This Row],[Check-in]] -> 2 | K199: 45 | L199: 0 | M199: =(J199*K199)-L199 -> 90 | N199: =Bookings[[#This Row],[Nights Stayed]]*Bookings[[#This Row],[Price per Night]] -> 90 | O199: =TEXT(Bookings[[#This Row],[Check-in]],"mmm") -> Aug | P199: Phone Call | Q199: Maria
A200: 2025-199 | B200: confirmed | C200: C168 | D200: 2 | E200: 3 | F200: {=_xlfn.IFS(Bookings[[#This Row],[Total Guests]]=1,"Solo",Bookings[[#This Row],[Total Guests]]=2,"Couple",Bookings[[#This Row],[Total Guests]]>=3,"Family")} -> Family | G200: =VLOOKUP(Bookings[[#This Row],[Guest ID]],Table1[],4,0) -> Greece | H200: 45897 | I200: 45898 | J200: =Bookings[[#This Row],[Check-out]]-Bookings[[#This Row],[Check-in]] -> 1 | K200: 47 | L200: 0 | M200: =(J200*K200)-L200 -> 47 | N200: =Bookings[[#This Row],[Nights Stayed]]*Bookings[[#This Row],[Price per Night]] -> 47 | O200: =TEXT(Bookings[[#This Row],[Check-in]],"mmm") -> Aug | P200: Walk in | Q200: Katerina
A201: 2025-200 | B201: confirmed | C201: C170 | D201: 103 | E201: 3 | F201: {=_xlfn.IFS(Bookings[[#This Row],[Total Guests]]=1,"Solo",Bookings[[#This Row],[Total Guests]]=2,"Couple",Bookings[[#This Row],[Total Guests]]>=3,"Family")} -> Family | G201: =VLOOKUP(Bookings[[#This Row],[Guest ID]],Table1[],4,0) -> MKD | H201: 45898 | I201: 45900 | J201: =Bookings[[#This Row],[Check-out]]-Bookings[[#This Row],[Check-in]] -> 2 | K201: 50 | L201: 0 | M201: =(J201*K201)-L201 -> 100 | N201: =Bookings[[#This Row],[Nights Stayed]]*Bookings[[#This Row],[Price per Night]] -> 100 | O201: =TEXT(Bookings[[#This Row],[Check-in]],"mmm") -> Aug | P201: Walk in | Q201: Maria
A202: 2025-201 | B202: confirmed | C202: C171 | D202: 2 | E202: 2 | F202: {=_xlfn.IFS(Bookings[[#This Row],[Total Guests]]=1,"Solo",Bookings[[#This Row],[Total Guests]]=2,"Couple",Bookings[[#This Row],[Total Guests]]>=3,"Family")} -> Couple | G202: =VLOOKUP(Bookings[[#This Row],[Guest ID]],Table1[],4,0) -> Serbia | H202: 45898 | I202: 45904 | J202: =Bookings[[#This Row],[Check-out]]-Bookings[[#This Row],[Check-in]] -> 6 | K202: 40 | L202: 0 | M202: =(J202*K202)-L202 -> 240 | N202: =Bookings[[#This Row],[Nights Stayed]]*Bookings[[#This Row],[Price per Night]] -> 240 | O202: =TEXT(Bookings[[#This Row],[Check-in]],"mmm") -> Aug | P202: Walk in | Q202: Dimitra
A203: 2025-202 | B203: confirmed | C203: C088 | D203: 102 | E203: 2 | F203: {=_xlfn.IFS(Bookings[[#This Row],[Total Guests]]=1,"Solo",Bookings[[#This Row],[Total Guests]]=2,"Couple",Bookings[[#This Row],[Total Guests]]>=3,"Family")} -> Couple | G203: =VLOOKUP(Bookings[[#This Row],[Guest ID]],Table1[],4,0) -> Belgium | H203: 45906 | I203: 45915 | J203: =Bookings[[#This Row],[Check-out]]-Bookings[[#This Row],[Check-in]] -> 9 | K203: 35 | L203: 0 | M203: =(J203*K203)-L203 -> 315 | N203: =Bookings[[#This Row],[Nights Stayed]]*Bookings[[#This Row],[Price per Night]] -> 315 | O203: =TEXT(Bookings[[#This Row],[Check-in]],"mmm") -> Sep | P203: Phone Call | Q203: Maria
... A222: 2025-221 | B222: confirmed | C222: C056 | D222: 3 | E222: 2 | F222: {=_xlfn.IFS(Bookings[[#This Row],[Total Guests]]=1,"Solo",Bookings[[#This Row],[Total Guests]]=2,"Couple",Bookings[[#This Row],[Total Guests]]>=3,"Family")} -> Couple | G222: =VLOOKUP(Bookings[[#This Row],[Guest ID]],Table1[],4,0) -> Serbia | H222: 45843 | I222: 45847 | J222: =Bookings[[#This Row],[Check-out]]-Bookings[[#This Row],[Check-in]] -> 4 | K222: 30 | L222: 0 | M222: =(J222*K222)-L222 -> 120 | N222: =Bookings[[#This Row],[Nights Stayed]]*Bookings[[#This Row],[Price per Night]] -> 120 | O222: =TEXT(Bookings[[#This Row],[Check-in]],"mmm") -> Jul | P222: Walk in | Q222: Maria
A223: =SUBTOTAL(103,Bookings[Booking ID]) -> 221 | N223: =SUBTOTAL(109,Bookings[Total Revenue]) -> 58477.216
B236: Row Labels | C236: Sum of Total Revenue
B237: Jun | C237: 9856
B238: Jul | C238: 20944.996
B239: Aug | C239: 21793.22
B240: Sep | C240: 5883
B241: Grand Total | C241: 58477.216

Sheet Expenses
A1: Date | B1: Month | C1: Main Category | D1: Description | E1: Amount
A2: 45836 | B2: =TEXT(A2,"mmm") -> Jun | C2: Taxes & Salary | D2: Salary Maria | E2: 800
A3: 45854 | B3: =TEXT(A3,"mmm") -> Jul | C3: Taxes & Salary | D3: Yearly Tax | E3: 5000
A4: 45867 | B4: =TEXT(A4,"mmm") -> Jul | C4: Taxes & Salary | D4: Salary Maria | E4: 800
A5: 45899 | B5: =TEXT(A5,"mmm") -> Aug | C5: Taxes & Salary | D5: Salary Maria | E5: 800
A6: 45899 | B6: =TEXT(A6,"mmm") -> Aug | C6: Taxes & Salary | D6: Salary Dimitra | E6: 500
A7: 45901 | B7: =TEXT(A7,"mmm") -> Sep | C7: Taxes & Salary | D7: Salary Grandma | E7: 1000 | H7: Main Category | I7: Desciption | J7: Total Expenses
A8: 45807 | B8: =TEXT(A8,"mmm") -> May | C8: Utilities | D8: Platform Subscription | E8: 120 | H8: Taxes & Salary | I8: Salary Maria | J8: =SUMIFS(Amount,Description,I8,Main_Category,H8) -> 2400
A9: 45810 | B9: =TEXT(A9,"mmm") -> Jun | C9: Utilities | D9: DEI | E9: 138
A10: 45825 | B10: =TEXT(A10,"mmm") -> Jun | C10: Utilities | D10: Vodafone | E10: 27.37
A11: 45827 | B11: =TEXT(A11,"mmm") -> Jun | C11: Utilities | D11: DEI | E11: 136
A12: 45839 | B12: =TEXT(A12,"mmm") -> Jul | C12: Utilities | D12: Vodafone | E12: 82
A13: 45859 | B13: =TEXT(A13,"mmm") -> Jul | C13: Utilities | D13: DEI | E13: 338 | H13: Row Labels | I13: Sum of Amount
A14: 45877 | B14: =TEXT(A14,"mmm") -> Aug | C14: Utilities | D14: Vodafone | E14: 2 | H14: May | I14: 272.32
A15: 45877 | B15: =TEXT(A15,"mmm") -> Aug | C15: Utilities | D15: Water Supply | E15: 136 | H15: Jun | I15: 3066.3
A16: 45886 | B16: =TEXT(A16,"mmm") -> Aug | C16: Utilities | D16: DEI | E16: 663 | H16: Jul | I16: 7651
A17: 45901 | B17: =TEXT(A17,"mmm") -> Sep | C17: Utilities | D17: Vodafone | E17: 32.5 | H17: Aug | I17: 4634.8
A18: 45925 | B18: =TEXT(A18,"mmm") -> Sep | C18: Utilities | D18: DEI | E18: 675 | H18: Sep | I18: 2499.5
A19: 45821 | B19: =TEXT(A19,"mmm") -> Jun | C19: Cleaning & Laundry | D19: Bedsheets | E19: 20 | H19: Grand Total | I19: 18123.92
A20: 45832 | B20: =TEXT(A20,"mmm") -> Jun | C20: Cleaning & Laundry | D20: Cleaning Staff | E20: 60
A21: 45833 | B21: =TEXT(A21,"mmm") -> Jun | C21: Cleaning & Laundry | D21: Cleaning Supplies | E21: 104.23
A22: 45836 | B22: =TEXT(A22,"mmm") -> Jun | C22: Cleaning & Laundry | D22: Cleaning Staff | E22: 30
A23: 45836 | B23: =TEXT(A23,"mmm") -> Jun | C23: Cleaning & Laundry | D23: Bedsheets | E23: 45
A24: 45838 | B24: =TEXT(A24,"mmm") -> Jun | C24: Cleaning & Laundry | D24: Cleaning Staff | E24: 60
A25: 45839 | B25: =TEXT(A25,"mmm") -> Jul | C25: Cleaning & Laundry | D25: Cleaning Staff | E25: 30
A26: 45843 | B26: =TEXT(A26,"mmm") -> Jul | C26: Cleaning & Laundry | D26: Bedsheets | E26: 47
A27: 45843 | B27: =TEXT(A27,"mmm") -> Jul | C27: Cleaning & Laundry | D27: Cleaning Supplies | E27: 13
A28: 45847 | B28: =TEXT(A28,"mmm") -> Jul | C28: Cleaning & Laundry | D28: Cleaning Staff | E28: 60
A29: 45847 | B29: =TEXT(A29,"mmm") -> Jul | C29: Cleaning & Laundry | D29: Cleaning Supplies | E29: 50
A30: 45849 | B30: =TEXT(A30,"mmm") -> Jul | C30: Cleaning & Laundry | D30: Cleaning Staff | E30: 30
A31: 45849 | B31: =TEXT(A31,"mmm") -> Jul | C31: Cleaning & Laundry | D31: Bedsheets | E31: 60
... A114: 45902 | B114: =TEXT(A114,"mmm") -> Sep | C114: Household & Miscellaneous | D114: Benzin | E114: 30

Sheet Monthly Summary
A1: Month | B1: Total Revenue | C1: Total Expenses | D1: Profit
A2: May | B2: =SUMIF(Bookings!O:O,Table4[[#This Row],[Month]],Bookings!N:N) -> 0 | C2: =SUMIF(Expenses!B:B,Table4[[#This Row],[Month]],Expenses!E:E) -> 272.32 | D2: =Table4[[#This Row],[Total Revenue]]-Table4[[#This Row],[Total Expenses]] -> -272.32
A3: Jun | B3: =SUMIF(Bookings!O:O,Table4[[#This Row],[Month]],Bookings!N:N) -> 9856 | C3: =SUMIF(Expenses!B:B,Table4[[#This Row],[Month]],Expenses!E:E) -> 3066.3 | D3: =Table4[[#This Row],[Total Revenue]]-Table4[[#This Row],[Total Expenses]] -> 6789.7
A4: Jul | B4: =SUMIF(Bookings!O:O,Table4[[#This Row],[Month]],Bookings!N:N) -> 20944.996 | C4: =SUMIF(Expenses!B:B,Table4[[#This Row],[Month]],Expenses!E:E) -> 7651 | D4: =Table4[[#This Row],[Total Revenue]]-Table4[[#This Row],[Total Expenses]] -> 13293.996
A5: Aug | B5: =SUMIF(Bookings!O:O,Table4[[#This Row],[Month]],Bookings!N:N) -> 21793.22 | C5: =SUMIF(Expenses!B:B,Table4[[#This Row],[Month]],Expenses!E:E) -> 4634.8 | D5: =Table4[[#This Row],[Total Revenue]]-Table4[[#This Row],[Total Expenses]] -> 17158.42
A6: Sep | B6: =SUMIF(Bookings!O:O,Table4[[#This Row],[Month]],Bookings!N:N) -> 5883 | C6: =SUMIF(Expenses!B:B,Table4[[#This Row],[Month]],Expenses!E:E) -> 2499.5 | D6: =Table4[[#This Row],[Total Revenue]]-Table4[[#This Row],[Total Expenses]] -> 3383.5

Sheet Pivots_Backend
B1: CUSTOMER ANALYSIS
A3: Count of Guest ID | B3: Column Labels | F3: Row Labels | G3: Count of Guest ID | I3: Row Labels | J3: Count of Booking ID
A4: Row Labels | B4: No | C4: Yes | D4: Grand Total | F4: Greece | G4: 0.36170213 | I4: Couple | J4: 118
A5: 18-30 | B5: 13 | C5: 5 | D5: 18 | F5: MKD | G5: 0.23404255 | I5: Family | J5: 89
A6: 31-50 | B6: 47 | C6: 27 | D6: 74 | F6: Other | G6: 0.053191489 | I6: Solo | J6: 14
A7: 51 plus | B7: 39 | C7: 52 | D7: 91 | F7: Serbia | G7: 0.35106383 | I7: Grand Total | J7: 221
A8: Grand Total | B8: 99 | C8: 84 | D8: 183 | F8: Grand Total | G8: 1
C11: Row Labels | D11: Average of Nights Stayed
C12: Austria | D12: 21 | G12: Row Labels | H12: Count of Booking ID
C13: Croatia | D13: 14 | G13: Grcka Info | H13: 8
C14: Switzerland | D14: 10 | G14: Messaging Apps | H14: 64
C15: Grand Total | D15: 17.428571 | G15: Phone Call | H15: 89
G16: Referral | H16: 4
G17: Social Media | H17: 22
G18: Walk in | H18: 34
G19: Grand Total | H19: 221
B22: REVENUE ANALYSIS
A24: Row Labels | B24: Sum of Total Revenue | E24: Row Labels | F24: Sum of Total Revenue
A25: Jun | B25: 9856 | E25: Serbia | F25: 26874.996
A26: Jul | B26: 20944.996 | E26: Greece | F26: 12434
A27: Aug | B27: 21793.22 | E27: MKD | F27: 11628
A28: Sep | B28: 5883 | E28: Other | F28: 7540.22
A29: Grand Total | B29: 58477.216 | E29: Grand Total | F29: 58477.216
B33: EXPENSES ANALYSIS
C35: Row Labels | D35: Sum of Amount | F35: Row Labels | G35: Sum of Amount
C36: Cleaning & Laundry | D36: 2137.23 | F36: May | G36: 272.32
C37: Household & Miscellaneous | D37: 1233.5 | F37: Jun | G37: 3066.3
C38: Maintenance | D38: 3503.32 | F38: Jul | G38: 7651
C39: Taxes & Salary | D39: 8900 | F39: Aug | G39: 4634.8
C40: Utilities | D40: 2349.87 | F40: Sep | G40: 2499.5
C41: Grand Total | D41: 18123.92 | F41: Grand Total | G41: 18123.92

Sheet Dashboard
A1: Cosmos Studios Season 2025 Analytics
B3: CUSTOMER ANALYSIS
B36: REVENUE ANALYSIS
B55: EXPENSES ANALYSIS
