Workbook

Sheet Guests
A1: Guest ID | B1: Age | C1: Age Group | D1: Country | E1: Returning Guest
A2: C001 | B2: 59 | C2: {=_xlfn.IFS(AND(B2>18,B2<=30),"18-30",AND(B2>30,B2<=50),"31-50",B2>50,"51 plus",TRUE,"")} -> 51 plus | D2: Serbia | E2: No
A3: C002 | B3: 37 | C3: {=_xlfn.IFS(AND(B3>18,B3<=30),"18-30",AND(B3>30,B3<=50),"31-50",B3>50,"51 plus",TRUE,"")} -> 31-50 | D3: Austria | E3: Yes
A4: C003 | B4: 56 | C4: {=_xlfn.IFS(AND(B4>18,B4<=30),"18-30",AND(B4>30,B4<=50),"31-50",B4>50,"51 plus",TRUE,"")} -> 51 plus | D4: Serbia | E4: Yes
A5: C004 | B5: 34 | C5: {=_xlfn.IFS(AND(B5>18,B5<=30),"18-30",AND(B5>30,B5<=50),"31-50",B5>50,"51 plus",TRUE,"")} -> 31-50 | D5: Serbia | E5: Yes
A6: C005 | B6: 57 | C6: {=_xlfn.IFS(AND(B6>18,B6<=30),"18-30",AND(B6>30,B6<=50),"31-50",B6>50,"51 plus",TRUE,"")} -> 51 plus | D6: Austria | E6: Yes
A7: C006 | B7: 54 | C7: {=_xlfn.IFS(AND(B7>18,B7<=30),"18-30",AND(B7>30,B7<=50),"31-50",B7>50,"51 plus",TRUE,"")} -> 51 plus | D7: Serbia | E7: Yes
A8: C007 | B8: 48 | C8: {=_xlfn.IFS(AND(B8>18,B8<=30),"18-30",AND(B8>30,B8<=50),"31-50",B8>50,"51 plus",TRUE,"")} -> 31-50 | D8: Serbia | E8: Yes
A9: C008 | B9: 42 | C9: {=_xlfn.IFS(AND(B9>18,B9<=30),"18-30",AND(B9>30,B9<=50),"31-50",B9>50,"51 plus",TRUE,"")} -> 31-50 | D9: Serbia | E9: Yes
A10: C009 | B10: 58 | C10: {=_xlfn.IFS(AND(B10>18,B10<=30),"18-30",AND(B10>30,B10<=50),"31-50",B10>50,"51 plus",TRUE,"")} -> 51 plus | D10: Serbia | E10: Yes
A11: C010 | B11: 50 | C11: {=_xlfn.IFS(AND(B11>18,B11<=30),"18-30",AND(B11>30,B11<=50),"31-50",B11>50,"51 plus",TRUE,"")} -> 31-50 | D11: Serbia | E11: Yes
A12: C011 | B12: 78 | C12: {=_xlfn.IFS(AND(B12>18,B12<=30),"18-30",AND(B12>30,B12<=50),"31-50",B12>50,"51 plus",TRUE,"")} -> 51 plus | D12: MKD | E12: Yes
A13: C012 | B13: 25 | C13: {=_xlfn.IFS(AND(B13>18,B13<=30),"18-30",AND(B13>30,B13<=50),"31-50",B13>50,"51 plus",TRUE,"")} -> 18-30 | D13: Serbia | E13: No
... A52: C051 | B52: 51 | C52: {=_xlfn.IFS(AND(B52>18,B52<=30),"18-30",AND(B52>30,B52<=50),"31-50",B52>50,"51 plus",TRUE,"")} -> 51 plus | D52: Greece | E52: No
A53: C052 | C53: {=_xlfn.IFS(AND(B53>18,B53<=30),"18-30",AND(B53>30,B53<=50),"31-50",B53>50,"51 plus",TRUE,"")} | D53: Greece | E53: No
A54: C053 | B54: 75 | C54: {=_xlfn.IFS(AND(B54>18,B54<=30),"18-30",AND(B54>30,B54<=50),"31-50",B54>50,"51 plus",TRUE,"")} -> 51 plus | D54: Greece | E54: Yes
A55: C054 | B55: 62 | C55: {=_xlfn.IFS(AND(B55>18,B55<=30),"18-30",AND(B55>30,B55<=50),"31-50",B55>50,"51 plus",TRUE,"")} -> 51 plus | D55: Greece | E55: No
A56: C055 | B56: 42 | C56: {=_xlfn.IFS(AND(B56>18,B56<=30),"18-30",AND(B56>30,B56<=50),"31-50",B56>50,"51 plus",TRUE,"")} -> 31-50 | D56: Greece | E56: No
A57: C056 | B57: 71 | C57: {=_xlfn.IFS(AND(B57>18,B57<=30),"18-30",AND(B57>30,B57<=50),"31-50",B57>50,"51 plus",TRUE,"")} -> 51 plus | D57: Serbia | E57: Yes
A58: C057 | B58: 46 | C58: {=_xlfn.IFS(AND(B58>18,B58<=30),"18-30",AND(B58>30,B58<=50),"31-50",B58>50,"51 plus",TRUE,"")} -> 31-50 | D58: Greece | E58: No
A59: C058 | C59: {=_xlfn.IFS(AND(B59>18,B59<=30),"18-30",AND(B59>30,B59<=50),"31-50",B59>50,"51 plus",TRUE,"")} | D59: Greece | E59: No
A60: C059 | B60: 67 | C60: {=_xlfn.IFS(AND(B60>18,B60<=30),"18-30",AND(B60>30,B60<=50),"31-50",B60>50,"51 plus",TRUE,"")} -> 51 plus | D60: Greece | E60: No
A61: C060 | B61: 61 | C61: {=_xlfn.IFS(AND(B61>18,B61<=30),"18-30",AND(B61>30,B61<=50),"31-50",B61>50,"51 plus",TRUE,"")} -> 51 plus | D61: MKD | E61: Yes
A62: C061 | C62: {=_xlfn.IFS(AND(B62>18,B62<=30),"18-30",AND(B62>30,B62<=50),"31-50",B62>50,"51 plus",TRUE,"")} | D62: Greece | E62: No
A63: C062 | B63: 43 | C63: {=_xlfn.IFS(AND(B63>18,B63<=30),"18-30",AND(B63>30,B63<=50),"31-50",B63>50,"51 plus",TRUE,"")} -> 31-50 | D63: Serbia | E63: No
A64: C063 | B64: 58 | C64: {=_xlfn.IFS(AND(B64>18,B64<=30),"18-30",AND(B64>30,B64<=50),"31-50",B64>50,"51 plus",TRUE,"")} -> 51 plus | D64: Greece | E64: Yes
A65: C064 | C65: {=_xlfn.IFS(AND(B65>18,B65<=30),"18-30",AND(B65>30,B65<=50),"31-50",B65>50,"51 plus",TRUE,"")} | D65: Greece | E65: No
A66: C065 | B66: 67 | C66: {=_xlfn.IFS(AND(B66>18,B66<=30),"18-30",AND(B66>30,B66<=50),"31-50",B66>50,"51 plus",TRUE,"")} -> 51 plus | D66: Serbia | E66: Yes
A67: C066 | B67: 50 | C67: {=_xlfn.IFS(AND(B67>18,B67<=30),"18-30",AND(B67>30,B67<=50),"31-50",B67>50,"51 plus",TRUE,"")} -> 31-50 | D67: Greece | E67: Yes
A68: C067 | B68: 52 | C68: {=_xlfn.IFS(AND(B68>18,B68<=30),"18-30",AND(B68>30,B68<=50),"31-50",B68>50,"51 plus",TRUE,"")} -> 51 plus | D68: MKD | E68: Yes
A69: C068 | B69: 51 | C69: {=_xlfn.IFS(AND(B69>18,B69<=30),"18-30",AND(B69>30,B69<=50),"31-50",B69>50,"51 plus",TRUE,"")} -> 51 plus | D69: Greece | E69: Yes
A70: C069 | B70: 46 | C70: {=_xlfn.IFS(AND(B70>18,B70<=30),"18-30",AND(B70>30,B70<=50),"31-50",B70>50,"51 plus",TRUE,"")} -> 31-50 | D70: Greece | E70: No
A71: C070 | B71: 74 | C71: {=_xlfn.IFS(AND(B71>18,B71<=30),"18-30",AND(B71>30,B71<=50),"31-50",B71>50,"51 plus",TRUE,"")} -> 51 plus | D71: Greece | E71: Yes
A72: C071 | B72: 69 | C72: {=_xlfn.IFS(AND(B72>18,B72<=30),"18-30",AND(B72>30,B72<=50),"31-50",B72>50,"51 plus",TRUE,"")} -> 51 plus | D72: Greece | E72: Yes
A73: C072 | B73: 34 | C73: {=_xlfn.IFS(AND(B73>18,B73<=30),"18-30",AND(B73>30,B73<=50),"31-50",B73>50,"51 plus",TRUE,"")} -> 31-50 | D73: Serbia | E73: Yes
A74: C073 | B74: 53 | C74: {=_xlfn.IFS(AND(B74>18,B74<=30),"18-30",AND(B74>30,B74<=50),"31-50",B74>50,"51 plus",TRUE,"")} -> 51 plus | D74: MKD | E74: No
A75: C074 | B75: 62 | C75: {=_xlfn.IFS(AND(B75>18,B75<=30),"18-30",AND(B75>30,B75<=50),"31-50",B75>50,"51 plus",TRUE,"")} -> 51 plus | D75: Serbia | E75: Yes
A76: C075 | B76: 31 | C76: {=_xlfn.IFS(AND(B76>18,B76<=30),"18-30",AND(B76>30,B76<=50),"31-50",B76>50,"51 plus",TRUE,"")} -> 31-50 | D76: Serbia | E76: No
A77: C076 | B77: 42 | C77: {=_xlfn.IFS(AND(B77>18,B77<=30),"18-30",AND(B77>30,B77<=50),"31-50",B77>50,"51 plus",TRUE,"")} -> 31-50 | D77: Greece | E77: Yes
... A120: C119 | B120: 34 | C120: {=_xlfn.IFS(AND(B120>18,B120<=30),"18-30",AND(B120>30,B120<=50),"31-50",B120>50,"51 plus",TRUE,"")} -> 31-50 | D120: MKD | E120: No
...

Sheet Bookings
A1: Booking ID | B1: Booking Status | C1: Guest ID | D1: Room No | E1: Total Guests | F1: Guest Type | G1: Guest Nationality | H1: Check-in | I1: Check-out | J1: Nights Stayed | K1: Price per Night | L1: Deposit | M1: Amount Due | N1: Total Revenue | O1: Month | P1: Booking Source | Q1: Contact Person
A2: 2025-001 | B2: confirmed | C2: C020 | D2: 108 | E2: 1 | F2: Solo | G2: =VLOOKUP(C2,Guests!$A$2:$E$189,4,0) -> Greece | H2: 45814 | I2: 45820 | J2: 6 | K2: 30 | L2: 0 | M2: =N2-L2 -> 180 | N2: =J2*K2 -> 180 | O2: Jun | P2: Phone Call | Q2: Dimitra
A3: 2025-002 | B3: confirmed | C3: C017 | D3: 104 | E3: 2 | F3: Couple | G3: =VLOOKUP(C3,Guests!$A$2:$E$189,4,0) -> Serbia | H3: 45814 | I3: 45816 | J3: 2 | K3: 30 | L3: 0 | M3: =N3-L3 -> 60 | N3: =J3*K3 -> 60 | O3: Jun | P3: Messaging Apps | Q3: Maria
A4: 2025-003 | B4: confirmed | C4: C017 | D4: 102 | E4: 3 | F4: Family | G4: =VLOOKUP(C4,Guests!$A$2:$E$189,4,0) -> Serbia | H4: 45814 | I4: 45816 | J4: 2 | K4: 35 | L4: 0 | M4: =N4-L4 -> 70 | N4: =J4*K4 -> 70 | O4: Jun | P4: Messaging Apps | Q4: Maria
A5: 2025-004 | B5: confirmed | C5: C011 | D5: 5 | E5: 4 | F5: Family | G5: =VLOOKUP(C5,Guests!$A$2:$E$189,4,0) -> MKD | H5: 45818 | I5: 45830 | J5: 12 | K5: 40 | L5: 0 | M5: =N5-L5 -> 480 | N5: =J5*K5 -> 480 | O5: Jun | P5: Messaging Apps | Q5: Maria
A6: 2025-005 | B6: confirmed | C6: C003 | D6: 108 | E6: 2 | F6: Couple | G6: =VLOOKUP(C6,Guests!$A$2:$E$189,4,0) -> Serbia | H6: 45821 | I6: 45831 | J6: 10 | K6: 30 | L6: 0 | M6: =N6-L6 -> 300 | N6: =J6*K6 -> 300 | O6: Jun | P6: Messaging Apps | Q6: Maria
A7: 2025-006 | B7: confirmed | C7: C018 | D7: 102 | E7: 3 | F7: Family | G7: =VLOOKUP(C7,Guests!$A$2:$E$189,4,0) -> Greece | H7: 45823 | I7: 45829 | J7: 6 | K7: 40 | L7: 0 | M7: =N7-L7 -> 240 | N7: =J7*K7 -> 240 | O7: Jun | P7: Phone Call | Q7: Dimitra
A8: 2025-007 | B8: confirmed | C8: C022 | D8: 8 | E8: 3 | F8: Family | G8: =VLOOKUP(C8,Guests!$A$2:$E$189,4,0) -> Serbia | H8: 45828 | I8: 45837 | J8: 9 | K8: 37 | L8: 0 | M8: =N8-L8 -> 333 | N8: =J8*K8 -> 333 | O8: Jun | P8: Grcka Info | Q8: Katerina
A9: 2025-008 | B9: confirmed | C9: C021 | D9: 5 | E9: 4 | F9: Family | G9: =VLOOKUP(C9,Guests!$A$2:$E$189,4,0) -> Greece | H9: 45830 | I9: 45836 | J9: 6 | K9: 45 | L9: 0 | M9: =N9-L9 -> 270 | N9: =J9*K9 -> 270 | O9: Jun | P9: Phone Call | Q9: Dimitra
A10: 2025-009 | B10: confirmed | C10: C019 | D10: 2 | E10: 2 | F10: Couple | G10: =VLOOKUP(C10,Guests!$A$2:$E$189,4,0) -> Greece | H10: 45832 | I10: 45838 | J10: 6 | K10: 35 | L10: 0 | M10: =N10-L10 -> 210 | N10: =J10*K10 -> 210 | O10: Jun | P10: Phone Call | Q10: Dimitra
A11: 2025-010 | B11: confirmed | C11: C016 | D11: 3 | E11: 2 | F11: Couple | G11: =VLOOKUP(C11,Guests!$A$2:$E$189,4,0) -> Serbia | H11: 45832 | I11: 45839 | J11: 7 | K11: 30 | L11: 0 | M11: =N11-L11 -> 210 | N11: =J11*K11 -> 210 | O11: Jun | P11: Messaging Apps | Q11: Maria
A12: 2025-011 | B12: confirmed | C12: C016 | D12: 4 | E12: 2 | F12: Couple | G12: =VLOOKUP(C12,Guests!$A$2:$E$189,4,0) -> Serbia | H12: 45832 | I12: 45839 | J12: 7 | K12: 30 | L12: 0 | M12: =N12-L12 -> 210 | N12: =J12*K12 -> 210 | O12: Jun | P12: Messaging Apps | Q12: Maria
A13: 2025-012 | B13: confirmed | C13: C023 | D13: 102 | E13: 2 | F13: Couple | G13: =VLOOKUP(C13,Guests!$A$2:$E$189,4,0) -> Serbia | H13: 45832 | I13: 45842 | J13: 10 | K13: 32 | L13: 0 | M13: =N13-L13 -> 320 | N13: =J13*K13 -> 320 | O13: Jun | P13: Messaging Apps | Q13: Katerina
... A222: 2025-221 | B222: confirmed | C222: C056 | D222: 3 | E222: 2 | F222: Couple | G222: =VLOOKUP(C222,Guests!$A$2:$E$189,4,0) -> Serbia | H222: 45843 | I222: 45847 | J222: 4 | K222: 30 | L222: 0 | M222: =N222-L222 -> 120 | N222: =J222*K222 -> 120 | O222: Jul | P222: Walk in | Q222: Maria

Sheet Expenses
A1: Date | B1: Month | C1: Main Category | D1: Description | E1: Amount
A2: 45821 | B2: Jun | C2: Cleaning & Laundry | D2: Bedsheets | E2: 20
A3: 45832 | B3: Jun | C3: Cleaning & Laundry | D3: Cleaning Staff | E3: 60
A4: 45833 | B4: Jun | C4: Cleaning & Laundry | D4: Cleaning Supplies | E4: 104.23
A5: 45836 | B5: Jun | C5: Cleaning & Laundry | D5: Cleaning Staff | E5: 30
A6: 45836 | B6: Jun | C6: Cleaning & Laundry | D6: Bedsheets | E6: 45
A7: 45838 | B7: Jun | C7: Cleaning & Laundry | D7: Cleaning Staff | E7: 60
A8: 45839 | B8: Jul | C8: Cleaning & Laundry | D8: Cleaning Staff | E8: 30
A9: 45843 | B9: Jul | C9: Cleaning & Laundry | D9: Bedsheets | E9: 47
A10: 45843 | B10: Jul | C10: Cleaning & Laundry | D10: Cleaning Supplies | E10: 13
A11: 45847 | B11: Jul | C11: Cleaning & Laundry | D11: Cleaning Staff | E11: 60
A12: 45847 | B12: Jul | C12: Cleaning & Laundry | D12: Cleaning Supplies | E12: 50
A13: 45849 | B13: Jul | C13: Cleaning & Laundry | D13: Cleaning Staff | E13: 30
... A114: 45925 | B114: Sep | C114: Utilities | D114: DEI | E114: 675
